Workbook
Name _1印: [1]社員リスト!#REF!
Name _DAT1: #REF!
Name _DAT2: #REF!
Name _DAT3: #REF!
Name _dat31: #REF!
Name _DAT4: #REF!
Name _DAT5: #REF!
Name _DAT6: #REF!
Name _DAT7: #REF!
Name _DAT8: #REF!
Name _DAT9: #REF!
Name BASE: #REF!
Name BASE2: #REF!
Name BCUnit: #REF!
Name DS_KEYS: #REF!
Name DS_NM: #REF!
Name EmployeeStatus: #REF!
Name Industry: #REF!
Name KEYS: #REF!
Name KMStatus: #REF!
Name NAMES: #REF!
Name NEC_KEYS: #REF!
Name Position: #REF!
Name ProjectStatus: #REF!
Name ServiceOffering: #REF!
Name Solution: #REF!
Name SYMBOL: #REF!
Name TBL_KEYS: #REF!
Name TBL_KEYS2: #REF!
Name TEST0: #REF!
Name TESTKEYS: #REF!
Name TESTVKEY: #REF!
Name WorthAReference: #REF!
Name グループ名: [4]マスタ!$A$4:$A$14
Name バージョン: #REF!
Name 作成者: #REF!
Name 作成日: #REF!
Name 承認者: #REF!
Name 承認日: #REF!
Name 店舗DF_KEYS: #REF!
Name 番号: [5]型TB!#REF!
Name 物流DF_KEYS: #REF!
Name 文書ID: #REF!

Sheet 表紙
N7: Version
N8: ='変更履歴 '!AY5 -> 0.1
L9: 作成日 | N9: 作成者
L10: ='変更履歴 '!X5 -> 46240 | N10: ='変更履歴 '!AE5 -> SAP
L11: 更新日 | N11: 更新者
L12: ='変更履歴 '!AJ5 -> 46240 | N12: ='変更履歴 '!AT5 -> SAP
L13: チーム
L14: ='変更履歴 '!AO5 -> 販売管理
C34: プロジェクト名称 | G34: Demoプロジェクト
C35: ドキュメント副題 | G35: カートン情報一括更新
C36: ドキュメント名称 | G36: XXXX_拡張開発要件定義書_ZSD0001_001_RD_カートン情報一括更新

Sheet 変更履歴 
B4: ドキュメント名称 | N4: ドキュメント副題 | X4: 作成日 | AE4: 作成者 | AJ4: 更新日 | AO4: チーム | AT4: 更新者 | AY4: Version
B5: =表紙!G36 -> XXXX_拡張開発要件定義書_ZSD0001_001_RD_カートン情報一括更新 | N5: =表紙!G35 -> カートン情報一括更新 | X5: =F8 -> 46240 | AE5: =P8 -> SAP | AJ5: =INDEX($F$8:$F$49,COUNTA($F$8:$F$49),1) -> 46240 | AO5: =INDEX($K$8:$K$49,COUNTA($K$8:$K$49),1) -> 販売管理 | AT5: =INDEX($P$8:$P$49,COUNTA($P$8:$P$49),1) -> SAP | AY5: =INDEX($B$8:$B$49,COUNTA($B$8:$B$49),1) -> 0.1
B7: Version | F7: 更新日 | K7: チーム | P7: 更新者 | U7: 承認日 | Z7: 承認者 | AH7: 変更概要
B8: 0.1 | F8: 46240 | K8: 販売管理 | P8: SAP | AH8: 新規作成

Sheet 機能要件 
A1: 拡張開発要件定義書
A2: 機能名称 | F2: カートン情報一括更新 | W2: 親機能ID | AB2: ZSD0001
A3: アドオン審査 | F3: アドオン審査カテゴリ | L3: 業務効率化要件
F4: Redmine番号 | W4: Redmine URL
F5: 目的・事由 | L5: ・XXXで附番したシリアル番号（Serial No.）およびロット番号（Batch No.）を用いてグローバルに製品管理を行う方針となった。 ・YYではカートンを開封せず、シリアル番号およびロット番号をカートン番号（Carton No.）に紐付けて管理する必要がある。 ・YYの入庫処理（GR：Goods Receipt）を効率化するために、航空運送状番号（Airway Bill No.）についてもカートン番号との紐付けが必要。 ・トレサビリティとYY側の入出庫の作業効率向上を両立するために本機能は不可欠。
A6: 業務要件概要
B8: 全体像
C9: XXXにて海外帳票を出力、出庫確認した後に、在庫管理レベルに応じたシリアル番号またはロット番号とAirway Bill No.をカートン番号に割当てる
C10: YYでは別機能を使って、上記カートン情報をもとに入庫処理を行う
B12: 業務要件
C13: 該当プロセス
D14: XXXからS/4導入済現法への輸出
C16: 業務要件概要
D17: XXXで附番したシリアル番号（Serial No.）およびロット番号（Batch No.）を用いてグローバルに製品管理を行う方針となった
D18: YYではカートンを開封せず、シリアル番号およびロット番号をカートン番号（Carton No.）に紐付けて管理する必要がある
D19: YYの入庫処理（GR：Goods Receipt）を効率化するために、航空運送状番号（Airway Bill No.）についてもカートン番号との紐付けが必要
D20: トレサビリティとYY側の入出庫の作業効率向上を両立するために本機能は不可欠
B22: 機能要件
C23: 機能概要
D24: アドオンテーブル(Carton Mapping Info)を用いて、出荷伝票、カートン番号、ロット番号、シリアル番号、Airway Bill Noの紐付け情報を管理するための
D25: Excelダウンロード・アップロード機能を提供する
D26: 会社間IDOC連携で作成されたトランザクションを処理対象とする
D27: 入力値の自動提案に際して、シリアル管理品かつロット管理品の品目は想定しない
D28: ダウンロードデータおよびダウンロード後のマニュアルでのファイル編集イメージについては補足参照
C30: 1. Excelダウンロード
D31: 画面上で入力した出荷ポイントを使って権限チェックを行う
D32: カートンNo.に対して、ロット、シリアル番号、Airway Bill No.をマッピングするために必要な情報をタブ区切りのCSVファイルとしてダウンロードし、
D33: Excelアップロードする際の元情報とする
D34: ダウンロードファイルのファイルパス、ファイル名は画面上で指定する
D36: 抽出条件
D37: 項目名 | L37: 取得元 | X37: 抽出条件
D38: 請求日付 | L38: 請求伝票明細-請求日付 | X38: 画面上で入力した値
D39: 請求伝票 | L39: 海外帳票情報明細-請求伝票 | X39: 画面上で入力した値
D40: 出荷ポイント | L40: 請求伝票明細-出荷ポイント | X40: 画面上で入力した値
D41: 請求先 | L41: 請求伝票明細-請求先 | X41: 画面上で入力した値
D42: 得意先購買発注タイプ | L42: 受注伝票ヘッダ-得意先購買発注タイプ | X42: 画面上で入力した値
Y43: 「IDOC連携あり」フラグがON：'DFUE' (データ転送)
Y44: 「IDOC連携なし」フラグがON：ブランク
D45: 削除フラグ | L45: 海外帳票情報ヘッダ-削除 | X45: ブランク
D47: ダウンロード項目
...

Sheet 業務フロー
A1: 拡張開発要件定義書
A2: 機能名称 | F2: ='機能要件 '!F2 -> カートン情報一括更新 | W2: 親機能ID | AB2: ='機能要件 '!AB2 -> ZSD0001
A3: Signavio URL | F3: － | W3: Signavio ID | AB3: －
A4: 補足、特記事項
A10: 業務フロー
A12: 頻度、スケジュール 役割・ｼｽﾃﾑ
A13: 担当者
A50: 管理者
A56: システム
A62: 補足説明
A74: 凡例

Sheet 画面遷移図
A1: 拡張開発要件定義書
A2: 機能名称 | F2: ='機能要件 '!F2 -> カートン情報一括更新 | W2: 親機能ID | AB2: ='機能要件 '!AB2 -> ZSD0001
A3: 画面遷移図

Sheet 画面定義
A1: 拡張開発要件定義書
A2: 機能名称 | F2: ='機能要件 '!F2 -> カートン情報一括更新 | W2: 親機能ID | AB2: ='機能要件 '!AB2 -> ZSD0001
A3: 画面定義
A4: No | F4: 1 | M4: 画面名
A5: 画面概要
A10: 画面レイアウト
A55: 画面項目定義
A56: No | B56: 項目タイプ | F56: 項目名 | N56: データソース | Y56: 必須 | AA56: 入出力 | AD56: 項目編集・ボタン仕様・その他補足
A57: 1 | B57: 検索項目 | F57: 請求日付 | N57: - | Y57: ○ | AA57: 入力可 | AD57: ダウンロードの時は必須 アップロードの時は任意
A58: 2 | B58: 検索項目 | F58: 請求伝票 | N58: - | AA58: 入力可
A59: 3 | B59: 検索項目 | F59: 出荷ポイント | N59: - | Y59: ○ | AA59: 入力可 | AD59: ダウンロードの時は必須 アップロードの時は任意
A60: 4 | B60: 検索項目 | F60: 請求先 | N60: - | AA60: 入力可
A61: 5 | B61: 検索項目 | F61: IDOC連携あり | N61: - | AA61: 入力可 | AD61: デフォルトON
A62: 6 | B62: 検索項目 | F62: IDOC連携なし | N62: - | AA62: 入力可 | AD62: デフォルトOFF
A63: 7 | B63: 検索項目 | F63: アップロード | AA63: 入力可 | AD63: アップロードかダウンロードか実行モードを指定する
A64: 8 | B64: 検索項目 | F64: ダウンロード | N64: - | AA64: 入力可 | AD64: アップロードかダウンロードか実行モードを指定する
A65: 9 | B65: 入出力項目 | F65: ファイルパス | N65: - | Y65: ○ | AA65: 入力可 | AD65: アップロード、ダウンロードデータのローカルファイルパス、ファイル名を指定する
A66: 10 | B66: 入出力項目 | F66: 出力ログ | N66: - | AA66: 入力可 | AD66: アップロード時に出力ログのローカルファイルパス、ファイル名を指定する
A67: 11
A68: 12
A69: 13

Sheet 帳票定義
A1: 拡張開発要件定義書
A2: 機能名称 | F2: ='機能要件 '!F2 -> カートン情報一括更新 | W2: 親機能ID | AB2: ='機能要件 '!AB2 -> ZSD0001
A3: 帳票定義
A4: No | M4: 帳票名
A5: 種類 | M5: 出力方法 | Y5: フォーム技術 | AK5: S/4 出力管理
A6: 用紙サイズ | M6: 縦/横
A7: 帳票概要
A15: 帳票レイアウト
A34: 帳票項目定義
A35: No | B35: 項目グループ | F35: ラベル | L35: 項目 | R35: データソース | AB35: 出力長 | AD35: 配置 | AG35: 備考
A36: 1
A37: 2
A38: 3
A39: 4
A40: 5
A41: 6
A42: 7
A43: 8
A44: 9
A45: 10

Sheet 補足
A1: 拡張開発要件定義書
A2: 機能名称 | F2: ='機能要件 '!F2 -> カートン情報一括更新 | W2: 親機能ID | AB2: ='機能要件 '!AB2 -> ZSD0001
A3: 補足
A4: 検討資料
B5: 機械翻訳版 | AW5: 元資料
B6: ■カートンのイメージ
C7: 固体、システム、レーザー
C36: 電子管
B66: ■カートン番号、出荷伝票番号、シリアル番号、ロット番号のデータリンクイメージ
A100: ■Excelダウロード後のファイル編集イメージ
D101: ※基本的に輸出品はロット管理またはシリアル管理されている。またロット管理かつシリアル管理はしない
D102: パターン
E103: 在庫管理レベル | S103: 海外情報明細の数量=出荷荷伝票明細の数量 | AH103: マニュアル編集が必要な項目
D104: A | E104: シリアル | S104: Yes | AH104: Airway Bill No.
D105: B | E105: シリアル | S105: No | AH105: Airway Bill No.、シリアル番号
D106: C | E106: ロット | S106: Yes | AH106: Airway Bill No.
D107: D | E107: ロット | S107: No | AH107: Airway Bill No.
D108: E | E108: ロット | N108: ロット分割あり | S108: Yes | AH108: Airway Bill No.
D109: F | E109: ロット | N109: ロット分割あり | S109: No | AH109: Airway Bill No.、数量
D110: G | E110: ロット管理なし、シリアル管理なし | S110: 判別なし | AH110: Airway Bill No.
D111: H | E111: 1シリアル 複数カートン | S111: Yes | AH111: Airway Bill No.
D113: イメージ
D114: パターンA | N114: パターンB | X114: パターンC | AI114: パターンD | AT114: パターンE | BF114: パターンF | BQ114: パターンG | CA114: パターンH
D130: パターンごとのデータ
E131: <海外帳票情報明細>
E132: 請求伝票 | I132: 請求伝票明細 | N132: 出荷伝票 | S132: 出荷伝票明細 | W132: 副明細 | Y132: 品目コード | AC132: 数量 | AE132: 単位 | AG132: シリアルNo. | AJ132: カートンNo.
D133: A | E133: 90000001 | I133: 10 | N133: 120000001 | S133: 10 | Y133: AAA | AC133: 5 | AE133: PC | AJ133: 1001
D134: B | E134: 90000001 | I134: 20 | N134: 120000002 | S134: 10 | Y134: BBB | AC134: 2 | AE134: PC | AJ134: 1002
D135: B | E135: 90000001 | I135: 20 | N135: 120000002 | S135: 10 | Y135: BBB | AC135: 3 | AE135: PC | AG135: 8-10 | AJ135: 1003
D136: C | E136: 90000001 | I136: 30 | N136: 120000003 | S136: 10 | Y136: CCC | AC136: 10 | AE136: PC | AJ136: 1004
D137: D | E137: 90000001 | I137: 40 | N137: 120000004 | S137: 10 | W137: 1 | Y137: DDD | AC137: 6 | AE137: PC | AJ137: 1005
D138: D | E138: 90000001 | I138: 40 | N138: 120000004 | S138: 10 | W138: 2 | Y138: DDD | AC138: 4 | AE138: PC | AJ138: 1006
D139: E | E139: 90000001 | I139: 50 | N139: 120000005 | S139: 10 | Y139: EEE | AC139: 10 | AE139: PC | AJ139: 1007
D140: F | E140: 90000001 | I140: 60 | N140: 120000006 | S140: 10 | W140: 1 | Y140: FFF | AC140: 4 | AE140: PC | AJ140: 1008
D141: F | E141: 90000001 | I141: 60 | N141: 120000006 | S141: 10 | W141: 2 | Y141: FFF | AC141: 6 | AE141: PC | AJ141: 1009
D142: G | E142: 90000001 | I142: 70 | N142: 120000007 | S142: 10 | Y142: GGG | AC142: 4 | AE142: PC | AJ142: 1010
D143: G | E143: 90000001 | I143: 70 | N143: 120000007 | S143: 10 | Y143: GGG | AC143: 3 | AE143: PC | AJ143: 1011
D144: H | E144: 90000001 | I144: 80 | N144: 120000008 | S144: 10 | W144: 1 | Y144: HHH | AC144: 1 | AE144: SET | AG144: 11 | AJ144: 1012
D145: H | E145: 90000001 | I145: 80 | N145: 120000008 | S145: 10 | W145: 2 | Y145: HHH | AC145: 1 | AE145: SET | AG145: 11 | AJ145: 1013
D146: H | E146: 90000001 | I146: 80 | N146: 120000008 | S146: 10 | W146: 3 | Y146: HHH | AC146: 1 | AE146: SET | AG146: 11 | AJ146: 1014
...

Sheet メモ(概要設計者向け) 
B2: （参考） | E2: サンプルプログラム

Sheet シート要否＆項目説明
A1: Sheet | B1: 項目 | C1: 説明 | D1: 要件定義タスクにおける記載要否(〇：必須、△：任意) | J1: XXX/SAP役割分担 | K1: 備考
D2: 画面系 | E2: 帳票系 | F2: 更新系 | G2: API(参照)系 | H2: UL/DL系 | I2: 標準拡張系
A3: ファイル名 | B3: - | C3: D231_拡張開発要件定義書_(要件定義文書ID)_(Title)_v0.1 例：D231_拡張開発要件定義書_ZEC0001_001_RD_経営管理レポート(販売管理)_v0.1 | D3: 〇 | E3: 〇 | F3: 〇 | G3: 〇 | H3: 〇 | I3: 〇 | J3: SAP | K3: 親機能IDに複数機能(追加開発ID)が紐づく場合、複数をまとめて１要件定義書にすることも可
A4: 表紙 | B4: ドキュメント副題 | C4: 機能名称を記載、(Title) と同様でもよい | D4: 〇 | E4: 〇 | F4: 〇 | G4: 〇 | H4: 〇 | I4: 〇 | J4: SAP
A5: 表紙 | B5: ドキュメント名称 | C5: ファイル名(バージョンは除く)を記載 例：D231_拡張開発要件定義書_ZEC0001_001_RD_経営管理レポート(販売管理) | D5: 〇 | E5: 〇 | F5: 〇 | G5: 〇 | H5: 〇 | I5: 〇 | J5: SAP
A6: 変更履歴 | B6: Version | C6: バージョンを記載(承認前まではマイナーアップデート) | D6: 〇 | E6: 〇 | F6: 〇 | G6: 〇 | H6: 〇 | I6: 〇 | J6: SAP
A7: 機能要件 | B7: 機能名称/親機能ID | C7: 機能名称と親機能IDを記載 | D7: 〇 | E7: 〇 | F7: 〇 | G7: 〇 | H7: 〇 | I7: 〇 | J7: SAP
A8: 機能要件 | B8: アドオン審査 | C8: アドオン審査の情報を記載 | D8: 〇 | E8: 〇 | F8: 〇 | G8: 〇 | H8: 〇 | I8: 〇 | J8: XXX | K8: 目的・事由が書ききれない場合は、Redmineに書いてある内容を参照できるようにリンクを貼るなどの対応にする
A9: 機能要件 | B9: 目的・事由 | C9: 開発に至った背景を記載 ※アドオン機能が必要となった経緯等、後からその機能が必要になった背景が分かるような内容を記入しておくこと | D9: 〇 | E9: 〇 | F9: 〇 | G9: 〇 | H9: 〇 | I9: 〇 | J9: XXX | K9: 追加開発申請の【実装の背景】および【機能概要】の転載も可
A10: 機能要件 | B10: 全体像 | C10: (任意)複数の要件定義書にまたがる機能など、全体図や処理の流れを見える化したほうが分かりやすい場合は、記載する。 | D10: △ | E10: △ | F10: △ | G10: △ | H10: △ | I10: △ | J10: XXX/SAP
A11: 機能要件 | B11: 業務要件 > 該当プロセス | C11: (任意)業務プロセスを明記したい場合は、記載する。 | D11: △ | E11: △ | F11: △ | G11: △ | H11: △ | I11: △ | J11: XXX
A12: 機能要件 | B12: 業務要件 > 業務要件概要 | C12: 機能的な所作ではなく、業務として可能としたいことを記載する。 | D12: 〇 | E12: 〇 | F12: 〇 | G12: 〇 | H12: 〇 | I12: 〇 | J12: XXX
A13: 機能要件 | B13: 機能要件 > 機能概要 | C13: 業務要件を実現するために必要な機能の概要を箇条書きで記載する。 ※前提条件/制約事項があれば記載(前提となる業務フロー・トランザクション機能、対象データの前提、マスタ・カスタマイジング設定の前提など) ※権限要件(会社コードや販売組織など組織コードに基づいた権限制御の要否など)があれば記載 | D13: 〇 | E13: 〇 | F13: 〇 | G13: 〇 | H13: 〇 | I13: 〇 | J13: SAP
A14: 機能要件 | B14: 機能要件 > 開発対象機能 | C14: 本要件に基づいて開発する機能を記載 ※追加開発一覧の記載につながるように、開発オブジェクト単位にある程度ブレイクダウンする | D14: 〇 | E14: 〇 | F14: 〇 | G14: 〇 | H14: 〇 | I14: 〇 | J14: SAP
A15: 機能要件 | B15: 非機能要件 > 想定利用者 | C15: 機能ごとに想定利用者数・頻度を記載 ※UI 開発を伴う場合は、必須記載。標準拡張は標準機能に準拠するため、記載不要(個別に要件があれば個別要件を記載)。 | D15: 〇 | E15: △ | F15: 〇 | G15: △ | H15: 〇 | I15: △ | J15: XXX
A16: 機能要件 | B16: 非機能要件 > 性能要件 | C16: 想定処理件数を記載。「XX 件 XX 分程度」などの処理時間要件の要件があれば追加で記載。 ※単独のアドオンの場合（単体レポートプログラムやUI開発を伴う機能）については記載する | D16: 〇 | E16: △ | F16: 〇 | G16: △ | H16: 〇 | I16: △ | J16: XXX
A17: 業務フロー | B17: 業務フロー | C17: Signavioに書き込むための下書きとしてOptionalで業務フローを記載 | D17: △ | E17: △ | F17: △ | G17: △ | H17: △ | I17: △ | J17: XXX | K17: アドオンによって新たな業務プロセスが定義される場合、任意で記載
A18: 画面遷移図 | B18: 画面遷移図 | C18: 開発対象機能一覧に含まれる画面の関係図を記載 | D18: 〇 | E18: △ | F18: △ | G18: - | H18: △ | I18: △ | J18: SAP | K18: ２画面以上で構成される機能の場合、必須。単純なポップアップ画面などは割愛可。 キーユーザ拡張ツールで自動生成されるUI(Fiori/GUI)についても割愛可。
A19: 画面定義 | B19: 画面レイアウト | C19: 画面レイアウトを記載 | D19: 〇 | E19: △ | F19: △ | G19: - | H19: 〇 | I19: △ | J19: XXX | K19: キーユーザ拡張ツールで自動生成されるUI(Fiori/GUI)、単純ポップアップ画面については割愛可
A20: 画面定義 | B20: 画面項目定義 | C20: 画面の項目情報を記載 | D20: △ | E20: △ | F20: △ | G20: - | H20: △ | I20: △ | J20: SAP | K20: 要件として細かく定義し合意をとる必要がある場合は記載
A21: 帳票定義 | B21: 帳票レイアウト | C21: 帳票レイアウトを記載 | D21: - | E21: 〇 | F21: - | G21: - | H21: 〇 | I21: △ | J21: XXX
A22: 帳票定義 | B22: 帳票項目定義 | C22: 帳票の項目情報を記載 | D22: - | E22: △ | F22: - | G22: - | H22: △ | I22: △ | J22: SAP | K22: 要件として細かく定義し合意をとる必要がある場合は記載
A23: 補足 | B23: - | C23: 補足説明があれば記載 | D23: △ | E23: △ | F23: △ | G23: △ | H23: △ | I23: △ | J23: SAP | K23: 補足は各シートにフリーテキストで記載してもよいが、本シートにまとめて記載してもよい
A24: メモ(概要設計者向け) | B24: - | C24: 概要設計に向けて技術的な情報や申し送り事項があれば記載 | D24: △ | E24: △ | F24: △ | G24: △ | H24: △ | I24: △ | J24: SAP | K24: 使用する拡張（SMOD、BAdI、Open FI、ルーチンなど）の ID や技術的な申し送り事項(CDS定義で必要な Annotation、使用したい権限オブジェクトなど)を記載
A26: ■補足資料・説明
A27: ●開発機能対象
A28: D013_追加開発申請手順（追加開発候補一覧）> シート：主たる機能分類選択ガイド より転載

Sheet メモ(概要設計者向け)
B2: （参考） | E2: 開発機検証時のスクリーンショット

Sheet リスト
A1: 開発対象機能>難易度 | B1: 開発対象機能>機能分類 | C1: 画面項目定義>項目タイプ | D1: 画面項目定義>入出力 | E1: 帳票定義>種類 | F1: 帳票定義>出力方法 | G1: 帳票定義>フォーム技術 | H1: 帳票定義>出力管理 | I1: 機能要件>アドオン審査カテゴリ
A2: 特大 | B2: BTP Fiori UI_Fiori Elements | C2: 検索項目 | D2: 入力可 | E2: （外部）法定帳票 | F2: 印刷 | G2: Adobe (Gateway) | H2: S4OC | I2: 法令要件
A3: 大 | B3: BTP Fiori UI_Fiori Free Style | C3: 入出力項目 | D3: 出力のみ | E3: （外部）仕入販売先関連 | F3: PDF | G3: Adobe (DDIC) | H3: NAST | I3: 対外的要件
A4: 中 | B4: BTPAPI_CAP | C4: 一覧項目 | E4: （外部）その他 | F4: 画面確認(PDF不要) | G4: SmartForm | H4: なし | I4: 事業優位性要件
A5: 小 | B5: S/4HANA_RAP | C5: アクションボタン | E5: （内部）内部指示書 | F5: その他 | G5: SAP Script | I5: 業務対応不可要件
A6: 特小 | B6: S/4HANA_Business WF拡張 | E6: （内部）その他 | I6: 業務効率化要件
A7: なし | B7: S/4HANA_Flexible Workflow拡張 | I7: 利便性向上要件
B8: S/4HANA_ABAP（Batch）
B9: S/4HANA_ABAP（レポート）
B10: S/4HANA_CDS View
B11: S/4HANA_Portal Site
B12: S/4HANA_KUT拡張（Custom Fields)
B13: S/4HANA_KUT拡張（Custom Logic)
B14: S/4HANA_KUT拡張（Custom Business Object)
B15: S/4HANA_拡張(Exit/BAdI/IDoc/BAPI拡張)
B16: S/4HANA_Adobe PDF Form
B17: その他_OS
B18: その他_HANA
B19: その他_その他

Sheet ①受信側記載要領
A1: インタフェースID | D1: DCTIF007 | G1: 送信側システム | L1: 担当者
A2: インタフェース名 | D2: 伝票明細 | G2: 受信側システム | K2: HAISHAくん（集中配車システム） | L2: 担当者
A4: No. | B4: Parent Structure | C4: 項目名 | D4: 項目ID | E4: 型 | F4: サイズ | I4: キー | J4: 必須 | K4: 項目説明 | L4: 書式 | M4: 設定値 | O4: 備考 | P4: IFマッピング情報 | S4: トランザクションマッピング情報 | AA4: No. | AB4: Parent Structure | AC4: 項目名 | AD4: 項目ID | AE4: 型 | AF4: サイズ | AI4: キー | AJ4: 必須 | AK4: 項目説明 | AL4: 書式 | AM4: 設定値 | AO4: 備考
B5: ※Idocの場合必須 | F5: 整数 | G5: 小数 | H5: バイト数 | M5: 例 | N5: 定義 | P5: No | Q5: 項目名 | R5: マッピングルール | S5: No | T5: 項目グループ | U5: 項目名（テキスト） | V5: 項目名 | W5: テーブル名 | X5: データタイプ | Y5: 桁数 | Z5: マッピングルール | AB5: ※Idocの場合必須 | AF5: 整数 | AG5: 小数 | AH5: バイト数 | AM5: 例 | AN5: 定義
A6: 1 | AA6: 1 | AC6: 処理日 | AE6: CHAR | AF6: - | AG6: - | AH6: 8 | AI6: ◎ | AJ6: ◎ | AK6: 業務日付を設定する。 | AL6: YYYYMMDD | AM6: 20170327
A7: 2 | AA7: 2 | AC7: 依頼番号 | AE7: CHAR | AF7: - | AG7: - | AH7: 9 | AI7: ◎ | AJ7: ◎ | AM7: 74562
A8: 3 | AA8: 3 | AC8: 伝票日付 | AE8: CHAR | AF8: - | AG8: - | AH8: 8 | AI8: ◎ | AJ8: ◎ | AL8: YYYYMMDD | AM8: 20170327
A9: 4 | AA9: 4 | AC9: 伝票番号 | AE9: CHAR | AF9: - | AG9: - | AH9: 7 | AI9: ◎ | AJ9: ◎ | AM9: 5812827
A10: 5 | AA10: 5 | AC10: 伝票番号枝番号 | AE10: CHAR | AF10: - | AG10: - | AH10: 2 | AI10: ◎ | AJ10: ◎ | AM10: 00
A11: 6 | AA11: 6 | AC11: 履歴番号 | AE11: CHAR | AF11: - | AG11: - | AH11: 2 | AI11: ◎ | AJ11: ◎ | AM11: 03
A12: 7 | AA12: 7 | AC12: 明細番号 | AE12: CHAR | AF12: - | AG12: - | AH12: 2 | AI12: ◎ | AJ12: ◎ | AM12: 01
A13: 8 | AA13: 8 | AC13: 商品コード | AE13: CHAR | AF13: - | AG13: - | AH13: 8 | AI13: - | AJ13: ◎ | AK13: ※実データは6桁で連携 | AM13: 335204 | AO13: ※IF定義書上は8桁で定義されているが、サンプルデータは6桁となっていたため、実態は6桁。
A14: 9 | AA14: 9 | AC14: 商品名 | AE14: CHAR | AF14: - | AG14: - | AH14: 32 | AI14: - | AJ14: - | AM14: キリン午後あたたかミル３４５Ｐ
A15: 10 | AA15: 10 | AC15: 商品分類区分 | AE15: CHAR | AF15: - | AG15: - | AH15: 2 | AI15: - | AJ15: - | AM15: 01
A16: 11 | AA16: 11 | AC16: 商品分類区分名称 | AE16: CHAR | AF16: - | AG16: - | AH16: 20 | AI16: - | AJ16: - | AM16: 製品
A17: 12 | AA17: 12 | AC17: ケース数 | AE17: CHAR | AF17: - | AG17: - | AH17: 5 | AI17: - | AJ17: ◎ | AM17: 64
A18: 13 | AA18: 13 | AC18: バラ数 | AE18: CHAR | AF18: - | AG18: - | AH18: 5 | AI18: - | AJ18: ◎ | AM18: 0
A19: 14 | AA19: 14 | AC19: マル特区分 | AE19: CHAR | AF19: - | AG19: - | AH19: 1 | AI19: - | AJ19: - | AN19: 0：無効、1：有効（マル特）
AF29: 2017/5/18追記：型TIMESTAMPの場合、サイズは未記載とする

Sheet ②トランザクション定義書とのマッピング内容記載要領
A1: インタフェースID | D1: DCTIF007 | G1: 送信側システム | L1: 担当者
A2: インタフェース名 | D2: 伝票明細 | G2: 受信側システム | K2: HAISHAくん（集中配車システム） | L2: 担当者
A4: No. | B4: Parent Structure | C4: 項目名 | D4: 項目ID | E4: 型 | F4: サイズ | I4: キー | J4: 必須 | K4: 項目説明 | L4: 書式 | M4: 設定値 | O4: 備考 | P4: IFマッピング情報 | S4: トランザクションマッピング情報 | AA4: No. | AB4: Parent Structure | AC4: 項目名 | AD4: 項目ID | AE4: 型 | AF4: サイズ | AI4: キー | AJ4: 必須 | AK4: 項目説明 | AL4: 書式 | AM4: 設定値 | AO4: 備考
B5: ※Idocの場合必須 | F5: 整数 | G5: 小数 | H5: バイト数 | M5: 例 | N5: 定義 | P5: No | Q5: 項目名 | R5: マッピングルール | S5: No | T5: 項目グループ | U5: 項目名（テキスト） | V5: 項目名 | W5: テーブル名 | X5: データタイプ | Y5: 桁数 | Z5: マッピングルール | AB5: ※Idocの場合必須 | AF5: 整数 | AG5: 小数 | AH5: バイト数 | AM5: 例 | AN5: 定義
A6: 1 | T6: 入出庫伝票ヘッダ | U6: 転記日付 | V6: BUDAT | W6: MKPF | X6: DATS | Y6: 8 | AA6: 1 | AC6: 処理日 | AE6: CHAR | AF6: - | AG6: - | AH6: 8 | AI6: ◎ | AJ6: ◎ | AK6: 業務日付を設定する。 | AL6: YYYYMMDD | AM6: 20170327
A7: 2 | T7: 入出庫伝票ヘッダ | U7: 入出庫伝票 | V7: MBLNR | W7: MKPF | X7: CHAR | Y7: 10 | Z7: 先頭1ケタを削除してセット | AA7: 2 | AC7: 依頼番号 | AE7: CHAR | AF7: - | AG7: - | AH7: 9 | AI7: ◎ | AJ7: ◎ | AM7: 74562
A8: 3 | T8: 入出庫伝票ヘッダ | U8: 伝票日付 | V8: BLDAT | W8: MKPF | X8: DATS | Y8: 8 | AA8: 3 | AC8: 伝票日付 | AE8: CHAR | AF8: - | AG8: - | AH8: 8 | AI8: ◎ | AJ8: ◎ | AL8: YYYYMMDD | AM8: 20170327
A9: 4 | T9: 入出庫伝票ヘッダ | U9: 入出庫伝票 | V9: MBLNR | W9: MKPF | X9: CHAR | Y9: 10 | Z9: 先頭3ケタを削除してセット | AA9: 4 | AC9: 伝票番号 | AE9: CHAR | AF9: - | AG9: - | AH9: 7 | AI9: ◎ | AJ9: ◎ | AM9: 5812827
A10: 5 | Z10: <ブランク> | AA10: 5 | AC10: 伝票番号枝番号 | AE10: CHAR | AF10: - | AG10: - | AH10: 2 | AI10: ◎ | AJ10: ◎ | AM10: 00
A11: 6 | Z11: <ブランク> | AA11: 6 | AC11: 履歴番号 | AE11: CHAR | AF11: - | AG11: - | AH11: 2 | AI11: ◎ | AJ11: ◎ | AM11: 03
A12: 7 | T12: 入出庫伝票明細 | U12: 明細番号 | V12: ZEILE | W12: MSEG | X12: NUMC | Y12: 4 | Z12: 先頭2ケタを削除してセット | AA12: 7 | AC12: 明細番号 | AE12: CHAR | AF12: - | AG12: - | AH12: 2 | AI12: ◎ | AJ12: ◎ | AM12: 01
A13: 8 | T13: 入出庫伝票明細 | U13: 品目コード | V13: MATNR | W13: MSEG | X13: CHAR | Y13: 40 | Z13: 商品変換テーブルを会社コードと品目コードで検索し抽出された商品コードをセットする。商品コードが抽出されない場合は＜ブランク＞をセット | AA13: 8 | AC13: 商品コード | AE13: CHAR | AF13: - | AG13: - | AH13: 8 | AI13: - | AJ13: ◎ | AK13: ※実データは6桁で連携 | AM13: 335204 | AO13: ※IF定義書上は8桁で定義されているが、サンプルデータは6桁となっていたため、実態は6桁。
A14: 9 | Z14: 品目コードより抽出された商品コードで商品変換テーブルより抽出した商品名称をセット。商品コードが抽出されない場合は＜ブランク＞をセット | AA14: 9 | AC14: 商品名 | AE14: CHAR | AF14: - | AG14: - | AH14: 32 | AI14: - | AJ14: - | AM14: キリン午後あたたかミル３４５Ｐ
A15: 10 | Z15: 固定値「V」 | AA15: 10 | AC15: 商品分類区分 | AE15: CHAR | AF15: - | AG15: - | AH15: 2 | AI15: - | AJ15: - | AM15: 01
A16: 11 | Z16: 固定値「飲料」 | AA16: 11 | AC16: 商品分類区分名称 | AE16: CHAR | AF16: - | AG16: - | AH16: 20 | AI16: - | AJ16: - | AM16: 製品
A17: 12 | T17: 入出庫伝票明細 | U17: 数量 | V17: MENGE | W17: MSEG | X17: QUAN | Y17: 13 | Z17: IF数量単位変換テーブルを基本数量単位で検索しIF換算係数を取得し、「IF換算係数x数量」の値をセットする | AA17: 12 | AC17: ケース数 | AE17: CHAR | AF17: - | AG17: - | AH17: 5 | AI17: - | AJ17: ◎ | AM17: 64
A18: 13 | T18: 入出庫伝票明細 | U18: 基本数量単位 | V18: MEINS | W18: MSEG | X18: UNIT | Y18: 3
A19: 14 | AA19: 13 | AC19: バラ数 | AE19: CHAR | AF19: - | AG19: - | AH19: 5 | AI19: - | AJ19: ◎ | AM19: 0
